<?xml version="1.0" encoding="utf-8"?>
<robot name="hoap3">
  <link name="base_link"></link>
  
  <link name="CHEST">
  	<inertial>
      <origin xyz="-0.049489 0.000892912 -0.0408259"></origin>
      <mass value="3.26"></mass>
      <inertia ixx="0.012195" ixy="0.00029548" ixz="0.000684" iyy="0.017564" iyz="0.00014579" izz="0.015671"></inertia>
    </inertial>
    <visual>
      <origin rpy="0.0 -0.0 0.0" xyz="0.0 0.0 0.0"></origin>
      <geometry>
        <mesh filename="/Users/fraisse/HOAP3-QP12/hoap3_description-master/meshes/BODY_LINK01.obj"></mesh>
      </geometry>
      <material name="white">
    	<color rgba="0.95 0.95 0.95 1"></color>
      </material>
    </visual>
    <collision>
    	<origin xyz="0 0 0" rpy="0 0 0"></origin>
    	<geometry>
    		<mesh filename="/Users/fraisse/HOAP3-QP12/hoap3_description-master/meshes/BODY_LINK01.obj"></mesh>
		</geometry>
	</collision>
  </link>
  
  <link name="H_PAN">
  	<inertial>
      <origin xyz="0.00539731 -0.00158067 0.0564034"></origin>
      <mass value="7.10e-02"></mass>
      <inertia ixx="6.9057e-05" ixy="1.0855e-06" ixz="-9.8369e-06" iyy="6.4124e-05" iyz="5.0894e-06" izz="3.3354e-05"></inertia>
    </inertial>
    <visual>
      <origin rpy="0.0 -0.0 1.57079632679" xyz="0.0 0.0 0.08"></origin>
      <geometry>
        <mesh filename="/Users/fraisse/HOAP3-QP12/hoap3_description-master/meshes/HEAD_LINK01.obj"></mesh>
      </geometry>
      <material name="grey">
    	<color rgba="0.6 0.6 0.6 1"></color>
      </material>
    </visual>
    <collision>
    	<origin xyz="0 0 0" rpy="0 0 0"></origin>
    	<geometry>
    		<mesh filename="/Users/fraisse/HOAP3-QP12/hoap3_description-master/meshes/HEAD_LINK01.obj"></mesh>
		</geometry>
	</collision>
  </link>
  
  <link name="H_ROLL">
    <inertial>
      <origin xyz="-0.00103952 -0.00517985 1.82267e-05"></origin>
      <mass value="4.12e-01"></mass>
      <inertia ixx="0.00055236" ixy="7.7732e-06" ixz="3.1787e-06" iyy="0.00073214" iyz="4.5778e-07" izz="0.00068213"></inertia>
    </inertial>
    <visual>
      <origin rpy="0.0 -0.0 0.0" xyz="0.0 0.0 0.0"></origin>
      <geometry>
        <mesh filename="/Users/fraisse/HOAP3-QP12/hoap3_description-master/meshes/HEAD_LINK02.obj"></mesh>
      </geometry>
      <material name="white">
    	<color rgba="0.95 0.95 0.95 1"></color>
      </material>
    </visual>
    <collision>
    	<origin xyz="0 0 0" rpy="0 0 0"></origin>
    	<geometry>
    		<mesh filename="/Users/fraisse/HOAP3-QP12/hoap3_description-master/meshes/HEAD_LINK02.obj"></mesh>
		</geometry>
	</collision>  
  </link>
  
  <link name="R_SFE">
    <inertial>
      <origin xyz="8.28367e-05 0.00666808 0.00634824"></origin>
      <mass value="2.10e-01"></mass>
      <inertia ixx="8.6669e-05" ixy="6.5852e-08" ixz="-5.2114e-07" iyy="6.6996e-05" iyz="3.2496e-06" izz="7.2962e-05"></inertia>
    </inertial>
    <visual>
      <origin rpy="0.0 -0.0 0.0" xyz="0.0 0.0 0.0"></origin>
      <geometry>
        <mesh filename="/Users/fraisse/HOAP3-QP12/hoap3_description-master/meshes/RARM_LINK01.obj"></mesh>
      </geometry>
      <material name="grey">
    	<color rgba="0.6 0.6 0.6 1"></color>
      </material>
    </visual>
    <collision>
    	<origin xyz="0 0 0" rpy="0 0 0"></origin>
    	<geometry>
    		<mesh filename="/Users/fraisse/HOAP3-QP12/hoap3_description-master/meshes/RARM_LINK01.obj"></mesh>
		</geometry>
	</collision>
  </link>
  
  <link name="R_SAA">
    <inertial>     
        <origin xyz="-0.00065756 -0.0463848 -0.00377395"></origin>
        <mass value="2.34e-01"></mass>
        <inertia ixx="0.00019021" ixy="4.38e-06" ixz="-1.911e-07" iyy="9.5565e-05" iyz="1.0948e-05" izz="0.00016691"></inertia>
    </inertial>
    <visual>
        <origin rpy="0.0 -0.0 0.0" xyz="0.0 0.0 0.0"></origin>
        <geometry>
            <mesh filename="/Users/fraisse/HOAP3-QP12/hoap3_description-master/meshes/RARM_LINK02.obj"></mesh>
        </geometry>
        <material name="white">
    	<color rgba="0.95 0.95 0.95 1"></color>
      </material>
    </visual>
    <collision>
    	<origin xyz="0 0 0" rpy="0 0 0"></origin>
    	<geometry>
    		<mesh filename="/Users/fraisse/HOAP3-QP12/hoap3_description-master/meshes/RARM_LINK02.obj"></mesh>
		</geometry>
	</collision>
  </link>
  
  <link name="R_SHR">
    <inertial>
      <origin xyz="-0.00272189 -0.00160245 -0.00220452"></origin>
      <mass value="1.965e-01"></mass>
      <inertia ixx="6.4997e-05" ixy="-1.2116e-07" ixz="1.2129e-06" iyy="5.2914e-05" iyz="6.02e-07" izz="6.8066e-05"></inertia>
    </inertial>
    <visual>
      <origin rpy="0.0 -0.0 0.0" xyz="0.0 0.0 0.0"></origin>
      <geometry>
        <mesh filename="/Users/fraisse/HOAP3-QP12/hoap3_description-master/meshes/RARM_LINK03.obj"></mesh>
      </geometry>
      <material name="white">
    	<color rgba="0.95 0.95 0.95 1"></color>
      </material>
    </visual>
    <collision>
    	<origin xyz="0 0 0" rpy="0 0 0"></origin>
    	<geometry>
    		<mesh filename="/Users/fraisse/HOAP3-QP12/hoap3_description-master/meshes/RARM_LINK03.obj"></mesh>
		</geometry>
	</collision>
  </link>
  
  <link name="R_EB">
    <inertial>
      <origin xyz="0.00100237 0.0664225 -0.000615512"></origin>
      <mass value="2.16e-01"></mass>
      <inertia ixx="0.00036057" ixy="-4.5324e-07" ixz="8.9511e-07" iyy="0.00010338" iyz="2.205e-05" izz="0.0003366"></inertia>
    </inertial>
    <visual>
      <origin rpy="0.0 -0.0 0.0" xyz="0.0 0.0 0.0"></origin>
      <geometry>
        <mesh filename="/Users/fraisse/HOAP3-QP12/hoap3_description-master/meshes/RARM_HAND.obj"></mesh>
      </geometry>
      <material name="white">
    	<color rgba="0.95 0.95 0.95 1"></color>
      </material>
    </visual>
    <collision>
    	<origin xyz="0 0 0" rpy="0 0 0"></origin>
    	<geometry>
    		<mesh filename="/Users/fraisse/HOAP3-QP12/hoap3_description-master/meshes/RARM_HAND.obj"></mesh>
		</geometry>
	</collision>
  </link>
  
   <link name="R_HAND"></link>
     
  <link name="L_SFE">
    <inertial>
      <origin xyz="-3.64197e-05 0.00664174 -0.00634825"></origin>
      <mass value="2.10e-01"></mass>
      <inertia ixx="8.6676e-05" ixy="8.5433e-08" ixz="2.1365e-07" iyy="6.6998e-05" iyz="-3.1487e-06" izz="7.2971e-05"></inertia>
    </inertial>
    <visual>
      <origin rpy="0.0 -0.0 0.0" xyz="0.0 0.0 0.0"></origin>
      <geometry>
        <mesh filename="/Users/fraisse/HOAP3-QP12/hoap3_description-master/meshes/LARM_LINK01.obj"></mesh>
      </geometry>
      <material name="grey">
    	<color rgba="0.6 0.6 0.6 1"></color>
      </material>
    </visual>
    <collision>
    	<origin xyz="0 0 0" rpy="0 0 0"></origin>
    	<geometry>
    		<mesh filename="/Users/fraisse/HOAP3-QP12/hoap3_description-master/meshes/LARM_LINK01.obj"></mesh>
		</geometry>
	</collision>
  </link>
  
  <link name="L_SAA">
    <inertial>
      <origin xyz="0.000747218 -0.0463619 -0.00377403"></origin>
      <mass value="2.34e-01"></mass>
      <inertia ixx="0.0001907" ixy="-4.5386e-06" ixz="4.7274e-07" iyy="9.5535e-05" iyz="1.082e-05" izz="0.00016738"></inertia>
    </inertial>
    <visual>
      <origin rpy="0.0 -0.0 0.0" xyz="0.0 0.0 0.0"></origin>
      <geometry>
        <mesh filename="/Users/fraisse/HOAP3-QP12/hoap3_description-master/meshes/LARM_LINK02.obj"></mesh>
      </geometry>
      <material name="white">
    	<color rgba="0.95 0.95 0.95 1"></color>
      </material>
    </visual>
    <collision>
    	<origin xyz="0 0 0" rpy="0 0 0"></origin>
    	<geometry>
    		<mesh filename="/Users/fraisse/HOAP3-QP12/hoap3_description-master/meshes/LARM_LINK02.obj"></mesh>
		</geometry>
	</collision>
  </link>
  
  <link name="L_SHR">
    <inertial>
      <origin xyz="-0.00270991 0.00160227 -0.00209019"></origin>
      <mass value="1.965e-01"></mass>
      <inertia ixx="6.5109e-05" ixy="1.2495e-07" ixz="1.6632e-06" iyy="5.3043e-05" iyz="-5.6632e-07" izz="6.8105e-05"></inertia>
    </inertial>
    <visual>
      <origin rpy="0.0 -0.0 0.0" xyz="0.0 0.0 0.0"></origin>
      <geometry>
        <mesh filename="/Users/fraisse/HOAP3-QP12/hoap3_description-master/meshes/LARM_LINK03.obj"></mesh>
      </geometry>
      <material name="white">
    	<color rgba="0.95 0.95 0.95 1"></color>
      </material>
    </visual>
    <collision>
    	<origin xyz="0 0 0" rpy="0 0 0"></origin>
    	<geometry>
    		<mesh filename="/Users/fraisse/HOAP3-QP12/hoap3_description-master/meshes/LARM_LINK03.obj"></mesh>
		</geometry>
	</collision>
  </link>
  
  <link name="L_EB">
    <inertial>
      <origin xyz="0.000962091 0.0664766 0.000558629"></origin>
      <mass value="2.16e-01"></mass>
      <inertia ixx="0.00035907" ixy="-7.3496e-07" ixz="-7.2663e-07" iyy="0.0001033" iyz="-2.223e-05" izz="0.00033523"></inertia>
    </inertial>
    <visual>
      <origin rpy="0.0 -0.0 0.0" xyz="0.0 0.0 0.0"></origin>
      <geometry>
        <mesh filename="/Users/fraisse/HOAP3-QP12/hoap3_description-master/meshes/LARM_HAND.obj"></mesh>
      </geometry>
      <material name="white">
    	<color rgba="0.95 0.95 0.95 1"></color>
      </material>
    </visual>
    <collision>
    	<origin xyz="0 0 0" rpy="0 0 0"></origin>
    	<geometry>
    		<mesh filename="/Users/fraisse/HOAP3-QP12/hoap3_description-master/meshes/LARM_HAND.obj"></mesh>
		</geometry>
	</collision>
  </link>
    
  <link name="L_HAND"></link>
  
  <link name="R_LR">
    <inertial>
      <origin xyz="-0.003015 -0.0022399 0.0335846"></origin>
      <mass value="5.87e-02"></mass>
      <inertia ixx="5.9825e-05" ixy="4.0769e-07" ixz="5.7046e-06" iyy="4.3205e-05" iyz="-2.9376e-06" izz="2.9576e-05"></inertia>
     </inertial>
    <visual>
      <origin rpy="0.0 -0.0 0.0" xyz="0.0 0.0 0.0"></origin>
      <geometry>
        <mesh filename="/Users/fraisse/HOAP3-QP12/hoap3_description-master/meshes/RLEG_LINK01.obj"></mesh>
      </geometry>
      <material name="grey">
    	<color rgba="0.6 0.6 0.6 1"></color>
      </material>
    </visual>
    <collision>
    	<origin xyz="0 0 0" rpy="0 0 0"></origin>
    	<geometry>
    		<mesh filename="/Users/fraisse/HOAP3-QP12/hoap3_description-master/meshes/RLEG_LINK01.obj"></mesh>
		</geometry>
	</collision>
  </link>
  
  <link name="R_LAA">
    <inertial>
      <origin xyz="-0.00272697 0.00113482 0.0023778"></origin>
      <mass value="2.10e-01"></mass>
      <inertia ixx="6.9414e-05" ixy="-8.936e-07" ixz="4.5001e-07" iyy="5.871e-05" iyz="5.1388e-07" izz="5.4737e-05"></inertia>
    </inertial>
    <visual>
      <origin rpy="0.0 -0.0 0.0" xyz="0.0 0.0 0.0"></origin>
      <geometry>
        <mesh filename="/Users/fraisse/HOAP3-QP12/hoap3_description-master/meshes/RLEG_LINK02.obj"></mesh>
      </geometry>
      <material name="grey">
    	<color rgba="0.6 0.6 0.6 1"></color>
      </material>
    </visual>
    <collision>
    	<origin xyz="0 0 0" rpy="0 0 0"></origin>
    	<geometry>
    		<mesh filename="/Users/fraisse/HOAP3-QP12/hoap3_description-master/meshes/RLEG_LINK02.obj"></mesh>
		</geometry>
	</collision>
  </link>
  
  <link name="R_LFE">
    <inertial>
       <origin xyz="-0.0698208 0.00616508 -0.00326392"></origin>
       <mass value="5.19e-01"></mass>
      <inertia ixx="0.00033344" ixy="-1.0466e-05" ixz="2.8618e-05" iyy="0.00071543" iyz="-1.8533e-05" izz="0.00066966"></inertia>
    </inertial>
    <visual>
      <origin rpy="0.0 -0.0 0.0" xyz="0.0 0.0 0.0"></origin>
      <geometry>
        <mesh filename="/Users/fraisse/HOAP3-QP12/hoap3_description-master/meshes/RLEG_LINK03.obj"></mesh>
      </geometry>
      <material name="white">
    	<color rgba="0.95 0.95 0.95 1"></color>
      </material>
    </visual>
    <collision>
    	<origin xyz="0 0 0" rpy="0 0 0"></origin>
    	<geometry>
    		<mesh filename="/Users/fraisse/HOAP3-QP12/hoap3_description-master/meshes/RLEG_LINK03.obj"></mesh>
		</geometry>
	</collision>
  </link>
  
  <link name="R_KN">
    <inertial>
      <origin xyz="-0.0508521 0.00536785 -0.0046975"></origin>
      <mass value="3.28e-01"></mass>
      <inertia ixx="0.000214" ixy="-2.6305e-05" ixz="-1.5271e-05" iyy="0.00033474" iyz="-9.4817e-06" izz="0.00027348"></inertia>
    </inertial>
    <visual>
      <origin rpy="0.0 -0.0 0.0" xyz="0.0 0.0 0.0"></origin>
      <geometry>
        <mesh filename="/Users/fraisse/HOAP3-QP12/hoap3_description-master/meshes/RLEG_LINK04.obj"></mesh>
      </geometry>
      <material name="white">
    	<color rgba="0.95 0.95 0.95 1"></color>
      </material>
    </visual>
    <collision>
    	<origin xyz="0 0 0" rpy="0 0 0"></origin>
    	<geometry>
    		<mesh filename="/Users/fraisse/HOAP3-QP12/hoap3_description-master/meshes/RLEG_LINK04.obj"></mesh>
		</geometry>
	</collision>
  </link>
  
  <link name="R_AFE">
    <inertial>
      <origin xyz="0.00293669 0.00366853 -0.00133746"></origin>
      <mass value="1.95e-01"></mass>
      <inertia ixx="6.3546e-05" ixy="2.9698e-07" ixz="-5.8574e-07" iyy="5.2975e-05" iyz="-9.5491e-07" izz="5.2791e-05"></inertia>
    </inertial>
    <visual>
      <origin rpy="0.0 -0.0 0.0" xyz="0.0 0.0 0.0"></origin>
      <geometry>
        <mesh filename="/Users/fraisse/HOAP3-QP12/hoap3_description-master/meshes/RLEG_LINK05.obj"></mesh>
      </geometry>
      <material name="grey">
    	<color rgba="0.6 0.6 0.6 1"></color>
      </material>
    </visual>
    <collision>
    	<origin xyz="0 0 0" rpy="0 0 0"></origin>
    	<geometry>
    		<mesh filename="/Users/fraisse/HOAP3-QP12/hoap3_description-master/meshes/RLEG_LINK05.obj"></mesh>
		</geometry>
	</collision>
  </link>
  
  <link name="R_AAA">
    <inertial>
      <origin xyz="-0.0292236 0.00324167 0.00827642"></origin>
      <mass value="1.54e-01"></mass>
      <inertia ixx="0.00021926" ixy="3.3018e-06" ixz="1.6341e-05" iyy="0.00017831" iyz="-3.4799e-06" izz="8.2035e-05"></inertia>
    </inertial>
    <visual>
      <origin rpy="0.0 -0.0 0.0" xyz="0.0 0.0 0.0"></origin>
      <geometry>
        <mesh filename="/Users/fraisse/HOAP3-QP12/hoap3_description-master/meshes/RLEG_LINK06.obj"></mesh>
      </geometry>
      <material name="white">
    	<color rgba="0.95 0.95 0.95 1"></color>
      </material>
    </visual>
    <collision>
    	<origin xyz="0 0 0" rpy="0 0 0"></origin>
    	<geometry>
    		<mesh filename="/Users/fraisse/HOAP3-QP12/hoap3_description-master/meshes/RLEG_LINK06.obj"></mesh>
		</geometry>
	</collision>
  </link>
  
  <link name="R_FOOT"></link>
  <link name="L_LR">
    <inertial>      
      <origin xyz="0.00300449 -0.00225088 0.0335846"></origin>
      <mass value="5.87e-02"></mass>
      <inertia ixx="5.9822e-05" ixy="-3.859e-07" ixz="-5.7159e-06" iyy="4.3208e-05" iyz="-2.9116e-06" izz="2.9577e-05"></inertia>
    </inertial>
    <visual>
      <origin rpy="0.0 -0.0 0.0" xyz="0.0 0.0 0.0"></origin>
      <geometry>
        <mesh filename="/Users/fraisse/HOAP3-QP12/hoap3_description-master/meshes/LLEG_LINK01.obj"></mesh>
      </geometry>
      <material name="grey">
    	<color rgba="0.6 0.6 0.6 1"></color>
      </material>
    </visual>
    <collision>
    	<origin xyz="0 0 0" rpy="0 0 0"></origin>
    	<geometry>
    		<mesh filename="/Users/fraisse/HOAP3-QP12/hoap3_description-master/meshes/LLEG_LINK01.obj"></mesh>
		</geometry>
	</collision>
  </link>
  
  <link name="L_LAA">
    <inertial>      
      <origin xyz="-0.00271179 -0.00124723 0.00238665"></origin>
      <mass value="2.10e-01"></mass>
      <inertia ixx="6.9324e-05" ixy="5.1197e-07" ixz="4.4311e-07" iyy="5.857e-05" iyz="-6.1833e-07" izz="5.4556e-05"></inertia>
    </inertial>
    <visual>
      <origin rpy="0.0 -0.0 0.0" xyz="0.0 0.0 0.0"></origin>
      <geometry>
        <mesh filename="/Users/fraisse/HOAP3-QP12/hoap3_description-master/meshes/LLEG_LINK02.obj"></mesh>
      </geometry>
      <material name="grey">
    	<color rgba="0.6 0.6 0.6 1"></color>
      </material>
    </visual>
    <collision>
    	<origin xyz="0 0 0" rpy="0 0 0"></origin>
    	<geometry>
    		<mesh filename="/Users/fraisse/HOAP3-QP12/hoap3_description-master/meshes/LLEG_LINK02.obj"></mesh>
		</geometry>
	</collision>
  </link>
  
  <link name="L_LFE">
    <inertial>
       <origin xyz="-0.0699224 0.00627642 0.00331502"></origin>
       <mass value="5.19e-01"></mass>
      <inertia ixx="0.00033312" ixy="-1.043e-05" ixz="-2.9347e-05" iyy="0.00071436" iyz="2.1129e-05" izz="0.00066904"></inertia>
    </inertial>
    <visual>
      <origin rpy="0.0 -0.0 0.0" xyz="0.0 0.0 0.0"></origin>
      <geometry>
        <mesh filename="/Users/fraisse/HOAP3-QP12/hoap3_description-master/meshes/LLEG_LINK03.obj"></mesh>
      </geometry>
      <material name="white">
    	<color rgba="0.95 0.95 0.95 1"></color>
      </material>
    </visual>
    <collision>
    	<origin xyz="0 0 0" rpy="0 0 0"></origin>
    	<geometry>
    		<mesh filename="/Users/fraisse/HOAP3-QP12/hoap3_description-master/meshes/LLEG_LINK03.obj"></mesh>
		</geometry>
	</collision>
  </link>
  
  <link name="L_KN">
    <inertial>      
      <origin xyz="-0.0508386 0.00537031 0.00487773"></origin>
      <mass value="3.28e-01"></mass>
      <inertia ixx="0.00021099" ixy="-2.6283e-05" ixz="1.5836e-05" iyy="0.00033177" iyz="8.6072e-06" izz="0.00027352"></inertia>
    </inertial>
    <visual>
      <origin rpy="0.0 -0.0 0.0" xyz="0.0 0.0 0.0"></origin>
      <geometry>
        <mesh filename="/Users/fraisse/HOAP3-QP12/hoap3_description-master/meshes/LLEG_LINK04.obj"></mesh>
      </geometry>
      <material name="white">
    	<color rgba="0.95 0.95 0.95 1"></color>
      </material>
    </visual>
    <collision>
    	<origin xyz="0 0 0" rpy="0 0 0"></origin>
    	<geometry>
    		<mesh filename="/Users/fraisse/HOAP3-QP12/hoap3_description-master/meshes/LLEG_LINK04.obj"></mesh>
		</geometry>
	</collision>
  </link>
  
  <link name="L_AFE">
    <inertial>
      <origin xyz="0.00292057 0.00369219 0.00119731"></origin>
      <mass value="1.95e-01"></mass>
      <inertia ixx="6.3554e-05" ixy="2.6758e-07" ixz="8.6738e-07" iyy="5.3146e-05" iyz="8.9246e-07" izz="5.269e-05"></inertia>
    </inertial>
    <visual>
      <origin rpy="0.0 -0.0 0.0" xyz="0.0 0.0 0.0"></origin>
      <geometry>
        <mesh filename="/Users/fraisse/HOAP3-QP12/hoap3_description-master/meshes/LLEG_LINK05.obj"></mesh>
      </geometry>
      <material name="grey">
    	<color rgba="0.6 0.6 0.6 1"></color>
      </material>
    </visual>
    <collision>
    	<origin xyz="0 0 0" rpy="0 0 0"></origin>
    	<geometry>
    		<mesh filename="/Users/fraisse/HOAP3-QP12/hoap3_description-master/meshes/LLEG_LINK05.obj"></mesh>
		</geometry>
	</collision>
  </link>
  
  <link name="L_AAA">
    <inertial>     
      <origin xyz="-0.0292236 -0.0033462 0.00827642"></origin>
      <mass value="1.54e-01"></mass>
      <inertia ixx="0.00021916" ixy="-2.722e-06" ixz="1.6341e-05" iyy="0.00017831" iyz="2.8469e-06" izz="8.1929e-05"></inertia>
    </inertial>
    <visual>
      <origin rpy="0.0 -0.0 0.0" xyz="0.0 0.0 0.0"></origin>
      <geometry>
        <mesh filename="/Users/fraisse/HOAP3-QP12/hoap3_description-master/meshes/LLEG_LINK06.obj"></mesh>
      </geometry>
      <material name="white">
    	<color rgba="0.95 0.95 0.95 1"></color>
      </material>
    </visual>
    <collision>
    	<origin xyz="0 0 0" rpy="0 0 0"></origin>
    	<geometry>
    		<mesh filename="/Users/fraisse/HOAP3-QP12/hoap3_description-master/meshes/LLEG_LINK06.obj"></mesh>
		</geometry>
	</collision>
  </link>
  
  <link name="L_FOOT"></link>
  <link name="WAIST">
    <inertial>    
      <origin xyz="-0.0322707 0.0111375 -0.000329172"></origin>
      <mass value="4.17e-01"></mass>
      <inertia ixx="0.00066078" ixy="6.7465e-06" ixz="4.9344e-06" iyy="0.00064212" iyz="-1.5178e-06" izz="0.00017018"></inertia>
    </inertial>
    <visual>
      <origin rpy="0.0 -0.0 0.0" xyz="0.0 0.0 0.0"></origin>
      <geometry>
        <mesh filename="/Users/fraisse/HOAP3-QP12/hoap3_description-master/meshes/BODY_LINK02.obj"></mesh>
      </geometry>
    </visual>
    <collision>
    	<origin xyz="0 0 0" rpy="0 0 0"></origin>
    	<geometry>
    		<mesh filename="/Users/fraisse/HOAP3-QP12/hoap3_description-master/meshes/BODY_LINK02.obj"></mesh>
		</geometry>
	</collision>   
  </link>


  <joint name="base_link_WAIST_joint" type="fixed">
    <parent link="base_link"></parent>
    <child link="WAIST"></child>
    <origin rpy="1.57079632679 -0.0 0.0" xyz="0.0 0.0 0.0"></origin>
  </joint>
  <joint name="WAIST_CHEST_joint" type="revolute">
    <parent link="WAIST"></parent>
    <child link="CHEST"></child>
    <axis xyz="0 1 0"></axis>
    <limit effort="100" lower="0.0" upper="0.610865238198" velocity="100"></limit>
    <origin rpy="-1.57079632679 -0.0 0.0" xyz="-0.0 0.0 0.0"></origin>
  </joint>
  <joint name="CHEST_H_PAN_joint" type="revolute">
    <parent link="CHEST"></parent>
    <child link="H_PAN"></child>
    <axis xyz="0 0 1"></axis>
    <limit effort="100" lower="-1.0471975512" upper="1.0471975512" velocity="100"></limit>
    <origin rpy="0.0 -0.0 0.0" xyz="-0.035 0.0 0.125"></origin>
  </joint>
  <joint name="H_PAN_H_ROLL_joint" type="revolute">
    <parent link="H_PAN"></parent>
    <child link="H_ROLL"></child>
    <axis xyz="0 0 -1"></axis>
    <limit effort="100" lower="-0.785398163397" upper="0.261799387799" velocity="100"></limit>
    <origin rpy="-1.57079632679 -0.0 0.0" xyz="0.015 0.0 0.103"></origin>
  </joint>
  
  <joint name="CHEST_R_SFE_joint" type="revolute">
    <parent link="CHEST"></parent>
    <child link="R_SFE"></child>
    <axis xyz="0 0 1"></axis>
    <limit effort="100" lower="-1.57079632679" upper="2.44346095279" velocity="100"></limit>
    <origin rpy="-1.57079632679 -0.0 0.0" xyz="-0.035 -0.111 0.125"></origin>
  </joint>
  <joint name="R_SFE_R_SAA_joint" type="revolute">
    <parent link="R_SFE"></parent>
    <child link="R_SAA"></child>
    <axis xyz="0 0 1"></axis>
    <limit effort="100" lower="-1.57079632679" upper="0.0" velocity="100"></limit>
    <origin rpy="1.57079632679 -1.57079632679 0.0" xyz="0.0 0.0 0.0"></origin>
  </joint>
  <joint name="R_SAA_R_SHR_joint" type="revolute">
    <parent link="R_SAA"></parent>
    <child link="R_SHR"></child>
    <axis xyz="0 0 1"></axis>
    <limit effort="100" lower="-1.57079632679" upper="1.57079632679" velocity="100"></limit>
    <origin rpy="1.57079632679 -1.57079632679 0.0" xyz="0.0 -0.111 0.0"></origin>
  </joint>
  <joint name="R_SHR_R_EB_joint" type="revolute">
    <parent link="R_SHR"></parent>
    <child link="R_EB"></child>
    <axis xyz="0 0 1"></axis>
    <limit effort="100" lower="-2.00712863979" upper="0.0" velocity="100"></limit>
    <origin rpy="1.57079632679 -0.0 0.0" xyz="0.0 0.0 0.0"></origin>
  </joint>
  <joint name="R_EB_R_HAND_joint" type="fixed">
    <parent link="R_EB"></parent>
    <child link="R_HAND"></child>
    <origin rpy="0.0 0.0 1.57079632679" xyz="0.0 0.171 0.0"></origin>
  </joint>
  
  <joint name="CHEST_L_SFE_joint" type="revolute">
    <parent link="CHEST"></parent>
    <child link="L_SFE"></child>
    <axis xyz="0 0 1"></axis>
    <limit effort="100" lower="-1.57079632679" upper="2.44346095279" velocity="100"></limit>
    <origin rpy="-1.57079632679 -0.0 0.0" xyz="-0.035 0.111 0.125"></origin>
  </joint>
  <joint name="L_SFE_L_SAA_joint" type="revolute">
    <parent link="L_SFE"></parent>
    <child link="L_SAA"></child>
    <axis xyz="0 0 1"></axis>
    <limit effort="100" lower="0.0" upper="1.57079632679" velocity="100"></limit>
    <origin rpy="1.57079632679 -1.57079632679 0.0" xyz="0.0 0.0 0.0"></origin>
  </joint>
  <joint name="L_SAA_L_SHR_joint" type="revolute">
    <parent link="L_SAA"></parent>
    <child link="L_SHR"></child>
    <axis xyz="0 0 1"></axis>
    <limit effort="100" lower="-1.58824961931" upper="1.58824961931" velocity="100"></limit>
    <origin rpy="1.57079632679 -1.57079632679 0.0" xyz="0.0 -0.111 0.0"></origin>
  </joint>
  <joint name="L_SHR_L_EB_joint" type="revolute">
    <parent link="L_SHR"></parent>
    <child link="L_EB"></child>
    <axis xyz="0 0 1"></axis>
    <limit effort="100" lower="-2.00712863979" upper="0.0" velocity="100"></limit>
    <origin rpy="1.57079632679 -0.0 0.0" xyz="0.0 0.0 0.0"></origin>
  </joint>
  <joint name="L_EB_L_HAND_joint" type="fixed">
    <parent link="L_EB"></parent>
    <child link="L_HAND"></child>
    <origin rpy="0.0 0.0 1.57079632679" xyz="0.0 0.171 0.0"></origin>
  </joint>
  
  <joint name="WAIST_R_LR_joint" type="revolute">
    <parent link="WAIST"></parent>
    <child link="R_LR"></child>
    <axis xyz="0 0 1"></axis>
    <limit effort="100" lower="-1.57079632679" upper="0.523598775598" velocity="100"></limit>
    <origin rpy="-1.57079632679 1.57079632679 0.0" xyz="-0.035 -0.055 0.039"></origin>
  </joint>
  <joint name="R_LR_R_LAA_joint" type="revolute">
    <parent link="R_LR"></parent>
    <child link="R_LAA"></child>
    <axis xyz="0 0 1"></axis>
    <limit effort="100" lower="-0.523598775598" upper="0.349065850399" velocity="100"></limit>
    <origin rpy="1.57079632679 -1.57079632679 0.0" xyz="0.0 0.0 0.0"></origin>
  </joint>
  <joint name="R_LAA_R_LFE_joint" type="revolute">
    <parent link="R_LAA"></parent>
    <child link="R_LFE"></child>
    <axis xyz="0 0 1"></axis>
    <limit effort="100" lower="-1.3962634016" upper="1.2217304764" velocity="100"></limit>
    <origin rpy="1.57079632679 -0.0 0.0" xyz="0.0 0.0 0.0"></origin>
  </joint>
  <joint name="R_LFE_R_KN_joint" type="revolute">
    <parent link="R_LFE"></parent>
    <child link="R_KN"></child>
    <axis xyz="0 0 1"></axis>
    <limit effort="100" lower="0.0872664625997" upper="2.26892802759" velocity="100"></limit>
    <origin rpy="0.0 -0.0 0.0" xyz="-0.105 0.0 0.0"></origin>
  </joint>
  <joint name="R_KN_R_AFE_joint" type="revolute">
    <parent link="R_KN"></parent>
    <child link="R_AFE"></child>
    <axis xyz="0 0 1"></axis>
    <limit effort="100" lower="-1.0471975512" upper="1.0471975512" velocity="100"></limit>
    <origin rpy="0.0 -0.0 0.0" xyz="-0.105 0.0 0.0"></origin>
  </joint>
  <joint name="R_AFE_R_AAA_joint" type="revolute">
    <parent link="R_AFE"></parent>
    <child link="R_AAA"></child>
    <axis xyz="0 0 1"></axis>
    <limit effort="100" lower="-0.436332312999" upper="0.436332312999" velocity="100"></limit>
    <origin rpy="-1.57079632679 -0.0 0.0" xyz="0.0 0.0 0.0"></origin>
  </joint>
  <joint name="R_AAA_R_FOOT_joint" type="fixed">
    <parent link="R_AAA"></parent>
    <child link="R_FOOT"></child>
    <origin rpy="0.0 -0.0 0.0" xyz="-0.04 0.005 0.014"></origin>
  </joint>
  
  <joint name="WAIST_L_LR_joint" type="revolute">
    <parent link="WAIST"></parent>
    <child link="L_LR"></child>
    <axis xyz="0 0 1"></axis>
    <limit effort="100" lower="-0.523598775598" upper="1.57079632679" velocity="100"></limit>
    <origin rpy="-1.57079632679 1.57079632679 0.0" xyz="-0.035 -0.055 -0.039"></origin>
  </joint>
  <joint name="L_LR_L_LAA_joint" type="revolute">
    <parent link="L_LR"></parent>
    <child link="L_LAA"></child>
    <axis xyz="0 0 1"></axis>
    <limit effort="100" lower="-0.349065850399" upper="0.523598775598" velocity="100"></limit>
    <origin rpy="1.57079632679 -1.57079632679 0.0" xyz="0.0 0.0 0.0"></origin>
  </joint>
  <joint name="L_LAA_L_LFE_joint" type="revolute">
    <parent link="L_LAA"></parent>
    <child link="L_LFE"></child>
    <axis xyz="0 0 1"></axis>
    <limit effort="100" lower="-1.3962634016" upper="1.2217304764" velocity="100"></limit>
    <origin rpy="1.57079632679 -0.0 0.0" xyz="0.0 0.0 0.0"></origin>
  </joint>
  <joint name="L_LFE_L_KN_joint" type="revolute">
    <parent link="L_LFE"></parent>
    <child link="L_KN"></child>
    <axis xyz="0 0 1"></axis>
    <limit effort="100" lower="0.0872664625997" upper="2.26892802759" velocity="100"></limit>
    <origin rpy="0.0 -0.0 0.0" xyz="-0.105 0.0 0.0"></origin>
  </joint>
  <joint name="L_KN_L_AFE_joint" type="revolute">
    <parent link="L_KN"></parent>
    <child link="L_AFE"></child>
    <axis xyz="0 0 1"></axis>
    <limit effort="100" lower="-1.0471975512" upper="1.0471975512" velocity="100"></limit>
    <origin rpy="0.0 -0.0 0.0" xyz="-0.105 0.0 0.0"></origin>
  </joint>
  <joint name="L_AFE_L_AAA_joint" type="revolute">
    <parent link="L_AFE"></parent>
    <child link="L_AAA"></child>
    <axis xyz="0 0 1"></axis>
    <limit effort="100" lower="-0.436332312999" upper="0.436332312999" velocity="100"></limit>
    <origin rpy="-1.57079632679 -0.0 0.0" xyz="0.0 0.0 0.0"></origin>
  </joint>
  <joint name="L_AAA_L_FOOT_joint" type="fixed">
    <parent link="L_AAA"></parent>
    <child link="L_FOOT"></child>
    <origin rpy="0.0 -0.0 0.0" xyz="-0.04 -0.005 0.014"></origin>
  </joint>
  
 </robot>

